<?xml version="1.0" encoding="utf-8"?>
<!-- This URDF was automatically created by SolidWorks to URDF Exporter! Originally created by Stephen Brawner (brawner@gmail.com) 
     Commit Version: 1.6.0-1-g15f4949  Build Version: 1.6.7594.29634
     For more information, please see http://wiki.ros.org/sw_urdf_exporter -->
<robot
  name="Car_sample">
  <link
    name="base_footprint_link">
    <inertial>
      <origin
        xyz="-2.7756E-17 2.7756E-17 0.06945"
        rpy="0 0 0" />
      <mass
        value="0.22089" />
      <inertia
        ixx="0.001658"
        ixy="-3.7231E-07"
        ixz="-5.9729E-22"
        iyy="0.0016546"
        iyz="4.5439E-22"
        izz="0.0033124" />
    </inertial>
    <visual>
      <origin
        xyz="0 0 0"
        rpy="0 0 0" />
      <geometry>
        <mesh
          filename="package://Car_sample/meshes/base_footprint_link.STL" />
      </geometry>
      <material
        name="">
        <color
          rgba="0.79216 0.81961 0.93333 1" />
      </material>
    </visual>
    <collision>
      <origin
        xyz="0 0 0"
        rpy="0 0 0" />
      <geometry>
        <mesh
          filename="package://Car_sample/meshes/base_footprint_link.STL" />
      </geometry>
    </collision>
  </link>
  <link
    name="base_Link">
    <inertial>
      <origin
        xyz="-2.7756E-17 2.7756E-17 0.00125"
        rpy="0 0 0" />
      <mass
        value="0.22089" />
      <inertia
        ixx="0.001658"
        ixy="-3.7231E-07"
        ixz="-5.8484E-22"
        iyy="0.0016546"
        iyz="4.5398E-22"
        izz="0.0033124" />
    </inertial>
    <visual>
      <origin
        xyz="0 0 0"
        rpy="0 0 0" />
      <geometry>
        <mesh
          filename="package://Car_sample/meshes/base_Link.STL" />
      </geometry>
      <material
        name="">
        <color
          rgba="0.79216 0.81961 0.93333 1" />
      </material>
    </visual>
    <collision>
      <origin
        xyz="0 0 0"
        rpy="0 0 0" />
      <geometry>
        <mesh
          filename="package://Car_sample/meshes/base_Link.STL" />
      </geometry>
    </collision>
  </link>
  <joint
    name="base_link_joint"
    type="fixed">
    <origin
      xyz="0 0 0.0682"
      rpy="0 0 0" />
    <parent
      link="base_footprint_link" />
    <child
      link="base_Link" />
    <axis
      xyz="0 0 0" />
  </joint>
  <link
    name="LF_link">
    <inertial>
      <origin
        xyz="5.4385E-08 0.14718 1.7232E-07"
        rpy="0 0 0" />
      <mass
        value="0.034412" />
      <inertia
        ixx="1.6337E-05"
        ixy="3.8986E-11"
        ixz="-9.4448E-11"
        iyy="2.8778E-05"
        iyz="1.5541E-11"
        izz="1.6337E-05" />
    </inertial>
    <visual>
      <origin
        xyz="0 0 0"
        rpy="0 0 0" />
      <geometry>
        <mesh
          filename="package://Car_sample/meshes/LF_link.STL" />
      </geometry>
      <material
        name="">
        <color
          rgba="0.25098 0.25098 0.25098 1" />
      </material>
    </visual>
    <collision>
      <origin
        xyz="0 0 0"
        rpy="0 0 0" />
      <geometry>
        <mesh
          filename="package://Car_sample/meshes/LF_link.STL" />
      </geometry>
    </collision>
  </link>
  <joint
    name="LF_joint"
    type="continuous">
    <origin
      xyz="0.08341 0.0023758 -0.0357"
      rpy="0 0 0" />
    <parent
      link="base_Link" />
    <child
      link="LF_link" />
    <axis
      xyz="0 1 0" />
  </joint>
  <link
    name="RF_Link">
    <inertial>
      <origin
        xyz="-0.093792 0.0043371 0.051983"
        rpy="0 0 0" />
      <mass
        value="2.7727" />
      <inertia
        ixx="0.02252"
        ixy="-0.00014419"
        ixz="0.0037902"
        iyy="0.026497"
        iyz="-0.00022838"
        izz="0.039987" />
    </inertial>
    <visual>
      <origin
        xyz="0 0 0"
        rpy="0 0 0" />
      <geometry>
        <mesh
          filename="package://Car_sample/meshes/RF_Link.STL" />
      </geometry>
      <material
        name="">
        <color
          rgba="1 1 1 1" />
      </material>
    </visual>
    <collision>
      <origin
        xyz="0 0 0"
        rpy="0 0 0" />
      <geometry>
        <mesh
          filename="package://Car_sample/meshes/RF_Link.STL" />
      </geometry>
    </collision>
  </link>
  <joint
    name="RF_joint"
    type="continuous">
    <origin
      xyz="0.08341 -0.0022242 -0.0357"
      rpy="0 0 0" />
    <parent
      link="base_Link" />
    <child
      link="RF_Link" />
    <axis
      xyz="0 1 0" />
  </joint>
  <link
    name="LB_Link">
    <inertial>
      <origin
        xyz="0.10756 -0.12346 0.05933"
        rpy="0 0 0" />
      <mass
        value="2.7727" />
      <inertia
        ixx="0.02252"
        ixy="-0.00014419"
        ixz="0.0037902"
        iyy="0.026497"
        iyz="-0.00022838"
        izz="0.039987" />
    </inertial>
    <visual>
      <origin
        xyz="0 0 0"
        rpy="0 0 0" />
      <geometry>
        <mesh
          filename="package://Car_sample/meshes/LB_Link.STL" />
      </geometry>
      <material
        name="">
        <color
          rgba="1 1 1 1" />
      </material>
    </visual>
    <collision>
      <origin
        xyz="0 0 0"
        rpy="0 0 0" />
      <geometry>
        <mesh
          filename="package://Car_sample/meshes/LB_Link.STL" />
      </geometry>
    </collision>
  </link>
  <joint
    name="LB_joint"
    type="continuous">
    <origin
      xyz="-0.11794 0.12558 -0.043047"
      rpy="0 0 0" />
    <parent
      link="base_Link" />
    <child
      link="LB_Link" />
    <axis
      xyz="0 1 0" />
  </joint>
  <link
    name="RB_Link">
    <inertial>
      <origin
        xyz="0.10756 0.12754 0.059331"
        rpy="0 0 0" />
      <mass
        value="2.7727" />
      <inertia
        ixx="0.02252"
        ixy="-0.00014419"
        ixz="0.0037902"
        iyy="0.026497"
        iyz="-0.00022838"
        izz="0.039987" />
    </inertial>
    <visual>
      <origin
        xyz="0 0 0"
        rpy="0 0 0" />
      <geometry>
        <mesh
          filename="package://Car_sample/meshes/RB_Link.STL" />
      </geometry>
      <material
        name="">
        <color
          rgba="1 1 1 1" />
      </material>
    </visual>
    <collision>
      <origin
        xyz="0 0 0"
        rpy="0 0 0" />
      <geometry>
        <mesh
          filename="package://Car_sample/meshes/RB_Link.STL" />
      </geometry>
    </collision>
  </link>
  <joint
    name="RB_joint"
    type="continuous">
    <origin
      xyz="-0.11794 -0.12542 -0.043048"
      rpy="0 0 0" />
    <parent
      link="base_Link" />
    <child
      link="RB_Link" />
    <axis
      xyz="0 1 0" />
  </joint>
</robot>